[2024-05-07T08:10:07.414+0000] {local_task_job_runner.py:120} INFO - ::group::Pre task execution logs
[2024-05-07T08:10:07.437+0000] {taskinstance.py:2073} INFO - Dependencies all met for dep_context=non-requeueable deps ti=<TaskInstance: trigger_airbyte_job_example.trigger_dbt_cloud_job manual__2024-05-07T08:08:48.989979+00:00 [queued]>
[2024-05-07T08:10:07.447+0000] {taskinstance.py:2073} INFO - Dependencies all met for dep_context=requeueable deps ti=<TaskInstance: trigger_airbyte_job_example.trigger_dbt_cloud_job manual__2024-05-07T08:08:48.989979+00:00 [queued]>
[2024-05-07T08:10:07.447+0000] {taskinstance.py:2303} INFO - Starting attempt 1 of 1
[2024-05-07T08:10:07.462+0000] {taskinstance.py:2327} INFO - Executing <Task(DbtCloudRunJobOperator): trigger_dbt_cloud_job> on 2024-05-07 08:08:48.989979+00:00
[2024-05-07T08:10:07.470+0000] {warnings.py:110} WARNING - /home/***/.local/lib/python3.12/site-packages/***/task/task_runner/standard_task_runner.py:61: DeprecationWarning: This process (pid=221) is multi-threaded, use of fork() may lead to deadlocks in the child.
  pid = os.fork()

[2024-05-07T08:10:07.471+0000] {standard_task_runner.py:63} INFO - Started process 223 to run task
[2024-05-07T08:10:07.473+0000] {standard_task_runner.py:90} INFO - Running: ['***', 'tasks', 'run', 'trigger_airbyte_job_example', 'trigger_dbt_cloud_job', 'manual__2024-05-07T08:08:48.989979+00:00', '--job-id', '160', '--raw', '--subdir', 'DAGS_FOLDER/dag_aribyte_ex.py', '--cfg-path', '/tmp/tmp4svp9ep0']
[2024-05-07T08:10:07.476+0000] {standard_task_runner.py:91} INFO - Job 160: Subtask trigger_dbt_cloud_job
[2024-05-07T08:10:07.531+0000] {task_command.py:426} INFO - Running <TaskInstance: trigger_airbyte_job_example.trigger_dbt_cloud_job manual__2024-05-07T08:08:48.989979+00:00 [running]> on host c811ecd915dc
[2024-05-07T08:10:07.634+0000] {taskinstance.py:2644} INFO - Exporting env vars: AIRFLOW_CTX_DAG_OWNER='***' AIRFLOW_CTX_DAG_ID='trigger_airbyte_job_example' AIRFLOW_CTX_TASK_ID='trigger_dbt_cloud_job' AIRFLOW_CTX_EXECUTION_DATE='2024-05-07T08:08:48.989979+00:00' AIRFLOW_CTX_TRY_NUMBER='1' AIRFLOW_CTX_DAG_RUN_ID='manual__2024-05-07T08:08:48.989979+00:00'
[2024-05-07T08:10:07.636+0000] {taskinstance.py:430} INFO - ::endgroup::
[2024-05-07T08:10:07.650+0000] {connection.py:274} WARNING - Connection schemes (type: dbt_cloud) shall not contain '_' according to RFC3986.
[2024-05-07T08:10:07.651+0000] {base.py:84} INFO - Using connection ID 'dbtconn' for task execution.
[2024-05-07T08:10:09.606+0000] {http.py:199} ERROR - HTTP error: Not Found
[2024-05-07T08:10:09.606+0000] {http.py:200} ERROR - {"status":{"code":404,"is_success":false,"user_message":"The requested resource was not found. Please check that you have the proper permissions. If you are seeing this in error, please contact support!","developer_message":""},"data":null}
[2024-05-07T08:10:09.607+0000] {taskinstance.py:441} INFO - ::group::Post task execution logs
[2024-05-07T08:10:09.618+0000] {taskinstance.py:2890} ERROR - Task failed with exception
Traceback (most recent call last):
  File "/home/airflow/.local/lib/python3.12/site-packages/airflow/providers/http/hooks/http.py", line 197, in check_response
    response.raise_for_status()
  File "/home/airflow/.local/lib/python3.12/site-packages/requests/models.py", line 1021, in raise_for_status
    raise HTTPError(http_error_msg, response=self)
requests.exceptions.HTTPError: 404 Client Error: Not Found for url: https://re888.us1.dbt.com/api/v2/accounts/70403103922109/jobs/70403108472524/run/

During handling of the above exception, another exception occurred:

Traceback (most recent call last):
  File "/home/airflow/.local/lib/python3.12/site-packages/airflow/models/taskinstance.py", line 465, in _execute_task
    result = _execute_callable(context=context, **execute_callable_kwargs)
             ^^^^^^^^^^^^^^^^^^^^^^^^^^^^^^^^^^^^^^^^^^^^^^^^^^^^^^^^^^^^^
  File "/home/airflow/.local/lib/python3.12/site-packages/airflow/models/taskinstance.py", line 432, in _execute_callable
    return execute_callable(context=context, **execute_callable_kwargs)
           ^^^^^^^^^^^^^^^^^^^^^^^^^^^^^^^^^^^^^^^^^^^^^^^^^^^^^^^^^^^^
  File "/home/airflow/.local/lib/python3.12/site-packages/airflow/models/baseoperator.py", line 400, in wrapper
    return func(self, *args, **kwargs)
           ^^^^^^^^^^^^^^^^^^^^^^^^^^^
  File "/home/airflow/.local/lib/python3.12/site-packages/airflow/providers/dbt/cloud/operators/dbt.py", line 147, in execute
    trigger_job_response = self.hook.trigger_job_run(
                           ^^^^^^^^^^^^^^^^^^^^^^^^^^
  File "/home/airflow/.local/lib/python3.12/site-packages/airflow/providers/dbt/cloud/hooks/dbt.py", line 66, in wrapper
    return func(*bound_args.args, **bound_args.kwargs)
           ^^^^^^^^^^^^^^^^^^^^^^^^^^^^^^^^^^^^^^^^^^^
  File "/home/airflow/.local/lib/python3.12/site-packages/airflow/providers/dbt/cloud/hooks/dbt.py", line 427, in trigger_job_run
    return self._run_and_get_response(
           ^^^^^^^^^^^^^^^^^^^^^^^^^^^
  File "/home/airflow/.local/lib/python3.12/site-packages/airflow/providers/dbt/cloud/hooks/dbt.py", line 317, in _run_and_get_response
    return self.run(endpoint=endpoint, data=payload)
           ^^^^^^^^^^^^^^^^^^^^^^^^^^^^^^^^^^^^^^^^^
  File "/home/airflow/.local/lib/python3.12/site-packages/airflow/providers/http/hooks/http.py", line 187, in run
    return self.run_and_check(session, prepped_request, extra_options)
           ^^^^^^^^^^^^^^^^^^^^^^^^^^^^^^^^^^^^^^^^^^^^^^^^^^^^^^^^^^^
  File "/home/airflow/.local/lib/python3.12/site-packages/airflow/providers/http/hooks/http.py", line 238, in run_and_check
    self.check_response(response)
  File "/home/airflow/.local/lib/python3.12/site-packages/airflow/providers/http/hooks/http.py", line 201, in check_response
    raise AirflowException(str(response.status_code) + ":" + response.reason)
airflow.exceptions.AirflowException: 404:Not Found
[2024-05-07T08:10:09.625+0000] {taskinstance.py:1205} INFO - Marking task as FAILED. dag_id=trigger_airbyte_job_example, task_id=trigger_dbt_cloud_job, execution_date=20240507T080848, start_date=20240507T081007, end_date=20240507T081009
[2024-05-07T08:10:09.639+0000] {standard_task_runner.py:110} ERROR - Failed to execute job 160 for task trigger_dbt_cloud_job (404:Not Found; 223)
[2024-05-07T08:10:09.655+0000] {local_task_job_runner.py:240} INFO - Task exited with return code 1
[2024-05-07T08:10:09.673+0000] {taskinstance.py:3482} INFO - 0 downstream tasks scheduled from follow-on schedule check
[2024-05-07T08:10:09.676+0000] {local_task_job_runner.py:222} INFO - ::endgroup::
