[2024-04-26T08:00:13.469+0000] {local_task_job_runner.py:120} INFO - ::group::Pre task execution logs
[2024-04-26T08:00:13.824+0000] {taskinstance.py:2073} INFO - Dependencies all met for dep_context=non-requeueable deps ti=<TaskInstance: trigger_airbyte_job_example.airbyte_trigger_file_feather_sync scheduled__2024-04-25T00:00:00+00:00 [queued]>
[2024-04-26T08:00:14.110+0000] {taskinstance.py:2073} INFO - Dependencies all met for dep_context=requeueable deps ti=<TaskInstance: trigger_airbyte_job_example.airbyte_trigger_file_feather_sync scheduled__2024-04-25T00:00:00+00:00 [queued]>
[2024-04-26T08:00:14.159+0000] {taskinstance.py:2303} INFO - Starting attempt 1 of 1
[2024-04-26T08:00:14.764+0000] {taskinstance.py:2327} INFO - Executing <Task(AirbyteTriggerSyncOperator): airbyte_trigger_file_feather_sync> on 2024-04-25 00:00:00+00:00
[2024-04-26T08:00:14.807+0000] {warnings.py:110} WARNING - /home/***/.local/lib/python3.12/site-packages/***/task/task_runner/standard_task_runner.py:61: DeprecationWarning: This process (pid=56) is multi-threaded, use of fork() may lead to deadlocks in the child.
  pid = os.fork()

[2024-04-26T08:00:14.810+0000] {standard_task_runner.py:63} INFO - Started process 72 to run task
[2024-04-26T08:00:14.805+0000] {standard_task_runner.py:90} INFO - Running: ['***', 'tasks', 'run', 'trigger_airbyte_job_example', 'airbyte_trigger_file_feather_sync', 'scheduled__2024-04-25T00:00:00+00:00', '--job-id', '100', '--raw', '--subdir', 'DAGS_FOLDER/dag_aribyte_ex.py', '--cfg-path', '/tmp/tmpgkcqdtay']
[2024-04-26T08:00:14.834+0000] {standard_task_runner.py:91} INFO - Job 100: Subtask airbyte_trigger_file_feather_sync
[2024-04-26T08:00:15.763+0000] {task_command.py:426} INFO - Running <TaskInstance: trigger_airbyte_job_example.airbyte_trigger_file_feather_sync scheduled__2024-04-25T00:00:00+00:00 [running]> on host ff62e46d2b31
[2024-04-26T08:00:18.639+0000] {taskinstance.py:2644} INFO - Exporting env vars: AIRFLOW_CTX_DAG_OWNER='***' AIRFLOW_CTX_DAG_ID='trigger_airbyte_job_example' AIRFLOW_CTX_TASK_ID='airbyte_trigger_file_feather_sync' AIRFLOW_CTX_EXECUTION_DATE='2024-04-25T00:00:00+00:00' AIRFLOW_CTX_TRY_NUMBER='1' AIRFLOW_CTX_DAG_RUN_ID='scheduled__2024-04-25T00:00:00+00:00'
[2024-04-26T08:00:18.643+0000] {taskinstance.py:430} INFO - ::endgroup::
[2024-04-26T08:00:18.779+0000] {base.py:84} INFO - Using connection ID '***_call_airbyte' for task execution.
[2024-04-26T08:00:20.160+0000] {http.py:199} ERROR - HTTP error: Conflict
[2024-04-26T08:00:20.160+0000] {http.py:200} ERROR - {"message":"A sync is already running for: 10aab3f3-a3fe-4fff-b776-007900a0ff31","exceptionClassName":"io.airbyte.commons.server.errors.ValueConflictKnownException","exceptionStack":["io.airbyte.commons.server.errors.ValueConflictKnownException: A sync is already running for: 10aab3f3-a3fe-4fff-b776-007900a0ff31","\tat io.airbyte.commons.server.handlers.SchedulerHandler.readJobFromResult(SchedulerHandler.java:804)","\tat io.airbyte.commons.server.handlers.SchedulerHandler.submitManualSyncToWorker(SchedulerHandler.java:774)","\tat io.airbyte.commons.server.handlers.SchedulerHandler.syncConnection(SchedulerHandler.java:565)","\tat io.airbyte.server.apis.ConnectionApiController.lambda$syncConnection$14(ConnectionApiController.java:233)","\tat io.airbyte.server.apis.ApiHelper.execute(ApiHelper.java:28)","\tat io.airbyte.server.apis.ConnectionApiController.syncConnection(ConnectionApiController.java:233)","\tat io.airbyte.server.apis.$ConnectionApiController$Definition$Exec.dispatch(Unknown Source)","\tat io.micronaut.context.AbstractExecutableMethodsDefinition$DispatchedExecutableMethod.invoke(AbstractExecutableMethodsDefinition.java:371)","\tat io.micronaut.context.DefaultBeanContext$4.invoke(DefaultBeanContext.java:594)","\tat io.micronaut.web.router.AbstractRouteMatch.execute(AbstractRouteMatch.java:303)","\tat io.micronaut.web.router.RouteMatch.execute(RouteMatch.java:111)","\tat io.micronaut.http.context.ServerRequestContext.with(ServerRequestContext.java:103)","\tat io.micronaut.http.server.RouteExecutor.lambda$executeRoute$14(RouteExecutor.java:659)","\tat reactor.core.publisher.FluxDeferContextual.subscribe(FluxDeferContextual.java:49)","\tat reactor.core.publisher.InternalFluxOperator.subscribe(InternalFluxOperator.java:62)","\tat reactor.core.publisher.FluxSubscribeOn$SubscribeOnSubscriber.run(FluxSubscribeOn.java:194)","\tat io.micronaut.reactive.reactor.instrument.ReactorInstrumentation.lambda$init$0(ReactorInstrumentation.java:62)","\tat reactor.core.scheduler.WorkerTask.call(WorkerTask.java:84)","\tat reactor.core.scheduler.WorkerTask.call(WorkerTask.java:37)","\tat io.micronaut.scheduling.instrument.InvocationInstrumenterWrappedCallable.call(InvocationInstrumenterWrappedCallable.java:53)","\tat java.base/java.util.concurrent.FutureTask.run(FutureTask.java:317)","\tat java.base/java.util.concurrent.ThreadPoolExecutor.runWorker(ThreadPoolExecutor.java:1144)","\tat java.base/java.util.concurrent.ThreadPoolExecutor$Worker.run(ThreadPoolExecutor.java:642)","\tat java.base/java.lang.Thread.run(Thread.java:1583)"]}
[2024-04-26T08:00:20.161+0000] {taskinstance.py:441} INFO - ::group::Post task execution logs
[2024-04-26T08:00:20.247+0000] {taskinstance.py:2890} ERROR - Task failed with exception
Traceback (most recent call last):
  File "/home/airflow/.local/lib/python3.12/site-packages/airflow/providers/http/hooks/http.py", line 197, in check_response
    response.raise_for_status()
  File "/home/airflow/.local/lib/python3.12/site-packages/requests/models.py", line 1021, in raise_for_status
    raise HTTPError(http_error_msg, response=self)
requests.exceptions.HTTPError: 409 Client Error: Conflict for url: http://host.docker.internal:8000/api/v1/connections/sync

During handling of the above exception, another exception occurred:

Traceback (most recent call last):
  File "/home/airflow/.local/lib/python3.12/site-packages/airflow/models/taskinstance.py", line 465, in _execute_task
    result = _execute_callable(context=context, **execute_callable_kwargs)
             ^^^^^^^^^^^^^^^^^^^^^^^^^^^^^^^^^^^^^^^^^^^^^^^^^^^^^^^^^^^^^
  File "/home/airflow/.local/lib/python3.12/site-packages/airflow/models/taskinstance.py", line 432, in _execute_callable
    return execute_callable(context=context, **execute_callable_kwargs)
           ^^^^^^^^^^^^^^^^^^^^^^^^^^^^^^^^^^^^^^^^^^^^^^^^^^^^^^^^^^^^
  File "/home/airflow/.local/lib/python3.12/site-packages/airflow/models/baseoperator.py", line 400, in wrapper
    return func(self, *args, **kwargs)
           ^^^^^^^^^^^^^^^^^^^^^^^^^^^
  File "/home/airflow/.local/lib/python3.12/site-packages/airflow/providers/airbyte/operators/airbyte.py", line 81, in execute
    job_object = hook.submit_sync_connection(connection_id=self.connection_id)
                 ^^^^^^^^^^^^^^^^^^^^^^^^^^^^^^^^^^^^^^^^^^^^^^^^^^^^^^^^^^^^^
  File "/home/airflow/.local/lib/python3.12/site-packages/airflow/providers/airbyte/hooks/airbyte.py", line 149, in submit_sync_connection
    return self.run(
           ^^^^^^^^^
  File "/home/airflow/.local/lib/python3.12/site-packages/airflow/providers/http/hooks/http.py", line 187, in run
    return self.run_and_check(session, prepped_request, extra_options)
           ^^^^^^^^^^^^^^^^^^^^^^^^^^^^^^^^^^^^^^^^^^^^^^^^^^^^^^^^^^^
  File "/home/airflow/.local/lib/python3.12/site-packages/airflow/providers/http/hooks/http.py", line 238, in run_and_check
    self.check_response(response)
  File "/home/airflow/.local/lib/python3.12/site-packages/airflow/providers/http/hooks/http.py", line 201, in check_response
    raise AirflowException(str(response.status_code) + ":" + response.reason)
airflow.exceptions.AirflowException: 409:Conflict
[2024-04-26T08:00:20.672+0000] {taskinstance.py:1205} INFO - Marking task as FAILED. dag_id=trigger_airbyte_job_example, task_id=airbyte_trigger_file_feather_sync, execution_date=20240425T000000, start_date=20240426T080013, end_date=20240426T080020
[2024-04-26T08:00:21.696+0000] {standard_task_runner.py:110} ERROR - Failed to execute job 100 for task airbyte_trigger_file_feather_sync (409:Conflict; 72)
[2024-04-26T08:00:21.828+0000] {local_task_job_runner.py:240} INFO - Task exited with return code 1
[2024-04-26T08:00:22.573+0000] {taskinstance.py:3482} INFO - 0 downstream tasks scheduled from follow-on schedule check
[2024-04-26T08:00:22.634+0000] {local_task_job_runner.py:222} INFO - ::endgroup::
