[2024-05-07T08:01:07.247+0000] {local_task_job_runner.py:120} INFO - ::group::Pre task execution logs
[2024-05-07T08:01:07.268+0000] {taskinstance.py:2073} INFO - Dependencies all met for dep_context=non-requeueable deps ti=<TaskInstance: trigger_airbyte_job_example.trigger_dbt_cloud_job manual__2024-05-07T07:59:54.860720+00:00 [queued]>
[2024-05-07T08:01:07.278+0000] {taskinstance.py:2073} INFO - Dependencies all met for dep_context=requeueable deps ti=<TaskInstance: trigger_airbyte_job_example.trigger_dbt_cloud_job manual__2024-05-07T07:59:54.860720+00:00 [queued]>
[2024-05-07T08:01:07.278+0000] {taskinstance.py:2303} INFO - Starting attempt 1 of 1
[2024-05-07T08:01:07.291+0000] {taskinstance.py:2327} INFO - Executing <Task(DbtCloudRunJobOperator): trigger_dbt_cloud_job> on 2024-05-07 07:59:54.860720+00:00
[2024-05-07T08:01:07.299+0000] {warnings.py:110} WARNING - /home/***/.local/lib/python3.12/site-packages/***/task/task_runner/standard_task_runner.py:61: DeprecationWarning: This process (pid=90) is multi-threaded, use of fork() may lead to deadlocks in the child.
  pid = os.fork()

[2024-05-07T08:01:07.300+0000] {standard_task_runner.py:63} INFO - Started process 92 to run task
[2024-05-07T08:01:07.301+0000] {standard_task_runner.py:90} INFO - Running: ['***', 'tasks', 'run', 'trigger_airbyte_job_example', 'trigger_dbt_cloud_job', 'manual__2024-05-07T07:59:54.860720+00:00', '--job-id', '154', '--raw', '--subdir', 'DAGS_FOLDER/dag_aribyte_ex.py', '--cfg-path', '/tmp/tmp5k6x4p0c']
[2024-05-07T08:01:07.303+0000] {standard_task_runner.py:91} INFO - Job 154: Subtask trigger_dbt_cloud_job
[2024-05-07T08:01:07.344+0000] {task_command.py:426} INFO - Running <TaskInstance: trigger_airbyte_job_example.trigger_dbt_cloud_job manual__2024-05-07T07:59:54.860720+00:00 [running]> on host c811ecd915dc
[2024-05-07T08:01:07.424+0000] {taskinstance.py:2644} INFO - Exporting env vars: AIRFLOW_CTX_DAG_OWNER='***' AIRFLOW_CTX_DAG_ID='trigger_airbyte_job_example' AIRFLOW_CTX_TASK_ID='trigger_dbt_cloud_job' AIRFLOW_CTX_EXECUTION_DATE='2024-05-07T07:59:54.860720+00:00' AIRFLOW_CTX_TRY_NUMBER='1' AIRFLOW_CTX_DAG_RUN_ID='manual__2024-05-07T07:59:54.860720+00:00'
[2024-05-07T08:01:07.426+0000] {taskinstance.py:430} INFO - ::endgroup::
[2024-05-07T08:01:07.435+0000] {connection.py:274} WARNING - Connection schemes (type: dbt_cloud) shall not contain '_' according to RFC3986.
[2024-05-07T08:01:07.435+0000] {base.py:84} INFO - Using connection ID 'dbt_conn' for task execution.
[2024-05-07T08:01:07.436+0000] {taskinstance.py:441} INFO - ::group::Post task execution logs
[2024-05-07T08:01:07.444+0000] {taskinstance.py:2890} ERROR - Task failed with exception
Traceback (most recent call last):
  File "/home/airflow/.local/lib/python3.12/site-packages/airflow/models/taskinstance.py", line 465, in _execute_task
    result = _execute_callable(context=context, **execute_callable_kwargs)
             ^^^^^^^^^^^^^^^^^^^^^^^^^^^^^^^^^^^^^^^^^^^^^^^^^^^^^^^^^^^^^
  File "/home/airflow/.local/lib/python3.12/site-packages/airflow/models/taskinstance.py", line 432, in _execute_callable
    return execute_callable(context=context, **execute_callable_kwargs)
           ^^^^^^^^^^^^^^^^^^^^^^^^^^^^^^^^^^^^^^^^^^^^^^^^^^^^^^^^^^^^
  File "/home/airflow/.local/lib/python3.12/site-packages/airflow/models/baseoperator.py", line 400, in wrapper
    return func(self, *args, **kwargs)
           ^^^^^^^^^^^^^^^^^^^^^^^^^^^
  File "/home/airflow/.local/lib/python3.12/site-packages/airflow/providers/dbt/cloud/operators/dbt.py", line 147, in execute
    trigger_job_response = self.hook.trigger_job_run(
                           ^^^^^^^^^^^^^^^^^^^^^^^^^^
  File "/home/airflow/.local/lib/python3.12/site-packages/airflow/providers/dbt/cloud/hooks/dbt.py", line 62, in wrapper
    raise AirflowException("Could not determine the dbt Cloud account.")
airflow.exceptions.AirflowException: Could not determine the dbt Cloud account.
[2024-05-07T08:01:07.448+0000] {taskinstance.py:1205} INFO - Marking task as FAILED. dag_id=trigger_airbyte_job_example, task_id=trigger_dbt_cloud_job, execution_date=20240507T075954, start_date=20240507T080107, end_date=20240507T080107
[2024-05-07T08:01:07.458+0000] {standard_task_runner.py:110} ERROR - Failed to execute job 154 for task trigger_dbt_cloud_job (Could not determine the dbt Cloud account.; 92)
[2024-05-07T08:01:07.474+0000] {local_task_job_runner.py:240} INFO - Task exited with return code 1
[2024-05-07T08:01:07.487+0000] {taskinstance.py:3482} INFO - 0 downstream tasks scheduled from follow-on schedule check
[2024-05-07T08:01:07.489+0000] {local_task_job_runner.py:222} INFO - ::endgroup::
